Workbook

Sheet Οδηγίες
A1: ΚΥΑ 1689/2025 και Microsoft 365: checklist συμμόρφωσης
A2: Πηγή απαιτήσεων | B2: ΚΥΑ αριθμ. 1689, «Εθνικό Πλαίσιο Απαιτήσεων Κυβερνοασφάλειας Βασικών και Σημαντικών Οντοτήτων», ΦΕΚ Β΄ 2186/6.5.2025, άρθρα 4 έως 25.
A3: Συντάκτης | B3: Δημοσθένης Αττέια, Microsoft 365 Security Insights. Η πλήρης σελίδα με φίλτρα και links: https://thecybersec.gr/kya-1689-2025/
A4: Έκδοση | B4: 30/10/2026
A5: Αποποίηση | B5: Η αντιστοίχιση είναι επαγγελματική ερμηνεία και όχι νομική συμβουλή. Μια ρύθμιση υποστηρίζει μια απαίτηση, δεν αποδεικνύει από μόνη της συμμόρφωση. Οι περιγραφές είναι σύντομες παραφράσεις. Για το ακριβές κείμενο ισχύει το ΦΕΚ.
A7: Πνευματικά δικαιώματα και όροι χρήσης
A8: Δικαιούχος | B8: © 2026 Δημοσθένης Αττέια, thecybersec.gr. Με επιφύλαξη παντός δικαιώματος.
A9: Τι προστατεύεται | B9: Η αντιστοίχιση των απαιτήσεων με ρυθμίσεις και εργαλεία της Microsoft, οι περιγραφές, τα τεκμήρια, τα σχόλια και η δομή του αρχείου είναι πρωτότυπο έργο του συντάκτη και προστατεύονται από τον ν. 2121/1993. Το κείμενο της ΚΥΑ 1689/2025 είναι δημόσιο έγγραφο και δεν αποτελεί αντικείμενο αυτής της προστασίας.
A10: Τι επιτρέπεται | B10: Η χρήση και η συμπλήρωση του αρχείου για τις εσωτερικές ανάγκες του οργανισμού σας, καθώς και η επίδειξή του σε ελεγκτές και αρμόδιες αρχές στο πλαίσιο ελέγχου.
A11: Τι απαγορεύεται χωρίς γραπτή άδεια του συντάκτη | B11: Η αναδημοσίευση, η αναδιανομή και η ανάρτηση του αρχείου ή τμήματός του σε ιστότοπους, πλατφόρμες ή μέσα κοινωνικής δικτύωσης. Η εμπορική εκμετάλλευση, μαζί με την ενσωμάτωσή του σε προϊόντα, υπηρεσίες, εκπαιδευτικό υλικό ή παραδοτέα προς τρίτους. Η αφαίρεση ή η αλλοίωση της αναφοράς στον συντάκτη και στην πηγή.
A12: Πώς το μοιράζεστε | B12: Με παραπομπή στη σελίδα https://thecybersec.gr/kya-1689-2025/, από όπου ο καθένας κατεβάζει την τρέχουσα έκδοση.
A13: Επικοινωνία για άδεια χρήσης | B13: Μέσω LinkedIn: https://www.linkedin.com/in/dimosthenisatteia/
A15: Πώς συμπληρώνεται
A16: Κίτρινες στήλες | B16: Στο φύλλο «Checklist» συμπληρώνετε μόνο τις κίτρινες στήλες: Κατάσταση, Υπεύθυνος, Τεκμήριο του οργανισμού, Ημερομηνία ελέγχου, Σημειώσεις. Οι υπόλοιπες στήλες είναι η αντιστοίχιση και δεν χρειάζεται να αλλάξουν.
A17: Κατάσταση | B17: Επιλέξτε από τη λίστα: Δεν ξεκίνησε, Σε εξέλιξη, Υλοποιήθηκε, Δεν εφαρμόζεται. Το φύλλο «Σύνοψη» υπολογίζει την ολοκλήρωση ανά άρθρο από αυτή τη στήλη.
A18: Στήλη «Αφορά» | B18: Οι γραμμές «Μόνο βασικές» δεν είναι υποχρεωτικές για τις σημαντικές οντότητες. Αν είστε σημαντική οντότητα, σημειώστε τις «Δεν εφαρμόζεται», εκτός αν τις υιοθετείτε προαιρετικά (άρθρο 3 παρ. 2 της ΚΥΑ).
A19: Παράδειγμα γραμμής | B19: 13.ζ | Κατάσταση: Υλοποιήθηκε | Υπεύθυνος: Υ.Α.Σ.Π.Ε. | Τεκμήριο του οργανισμού: Conditional Access policy «Require MFA for all users», εξαγωγή 15/09/2026 | Ημερομηνία ελέγχου: 15/09/2026
A20: Ολοκλήρωση | B20: Ποσοστό = Υλοποιήθηκε / (Απαιτήσεις − Δεν εφαρμόζεται). Οι γραμμές χωρίς κατάσταση μετρούν ως μη υλοποιημένες.
A22: Τύποι μέτρου
A23: Τεχνικό | B23: Υλοποιείται κυρίως με ρύθμιση προϊόντος Microsoft.
A24: Μικτό | B24: Χρειάζεται έγγραφο ή διαδικασία, και η Microsoft δίνει την τεχνική επιβολή ή το τεκμήριο.
A25: Οργανωτικό ή εκτός Microsoft 365 | B25: Δεν υπάρχει ρύθμιση που να το καλύπτει. Υλοποιείται με πολιτικές, διαδικασίες ή άλλα εργαλεία.
A26: Επιπλέον άδεια | B26: Προϊόν Microsoft που χρειάζεται άδεια πέρα από ένα τυπικό Microsoft 365 E3. Επιβεβαιώστε την αδειοδότηση με τον licensing partner σας.

Sheet Checklist
A1: Κωδικός | B1: Άρθρο | C1: Τίτλος άρθρου ΚΥΑ | D1: Αφορά | E1: Τι ζητά η ΚΥΑ (σύνοψη) | F1: Τύπος μέτρου | G1: Ρύθμιση ή εργαλείο Microsoft | H1: Πού βρίσκεται το τεκμήριο | I1: Επιπλέον άδεια | J1: Προσοχή | K1: Σχετικά άρθρα (thecybersec.gr) | L1: Κατάσταση | M1: Υπεύθυνος | N1: Τεκμήριο του οργανισμού | O1: Ημερομηνία ελέγχου | P1: Σημειώσεις
A2: 4.α | B2: 4 | C2: Υποχρεώσεις και ευθύνη των ανωτάτων οργάνων διοίκησης | D2: Βασικές και σημαντικές | E2: Ολοκληρωμένο πρόγραμμα διαχείρισης κινδύνων κυβερνοασφάλειας, με ευθύνη του ανώτατου οργάνου διοίκησης. | F2: Μικτό | G2: Microsoft Purview Compliance Manager (assessment «NIS2 Directive (EU) 2022/2555») ως μητρώο του προγράμματος. Microsoft Secure Score ως μετρήσιμη τεχνική βάση. | H2: Απόφαση/πρακτικό ΔΣ για το πρόγραμμα. Compliance Manager: βαθμολογία και κατάσταση improvement actions. | I2: Premium regulation του Compliance Manager για το NIS 2 (αγοράζεται ξεχωριστά, ή ως ένα από τα τρία δωρεάν premium regulations με Microsoft 365 E5) | K2: https://thecybersec.gr/posts/secure-score-grc-part-0-intro/ https://thecybersec.gr/posts/microsoft-secure-score-grc-programma-ciso/ https://thecybersec.gr/mitroo-politikon/
A3: 4.β | B3: 4 | C3: Υποχρεώσεις και ευθύνη των ανωτάτων οργάνων διοίκησης | D3: Βασικές και σημαντικές | E3: Το ανώτατο όργανο εγκρίνει και επιβλέπει το πρόγραμμα, διαθέτει πόρους, ενημερώνει το προσωπικό, λογοδοτεί και παρακολουθεί εκπαίδευση. | F3: Μικτό | G3: Αναφορά προς το ΔΣ με Secure Score και Compliance Manager. Attack simulation training και για τα μέλη της διοίκησης (περ. βε). | H3: Πρακτικά ΔΣ, εγκεκριμένος προϋπολογισμός, βεβαιώσεις εκπαίδευσης μελών ΔΣ. | I3: Microsoft Defender for Office 365 Plan 2 (Attack simulation training) | K3: https://thecybersec.gr/posts/secure-score-grc-part-0-intro/ https://thecybersec.gr/posts/microsoft-secure-score-grc-programma-ciso/ https://thecybersec.gr/tekmiriosi-ekpaideysis/ https://thecybersec.gr/mitroo-politikon/
A4: 5.1.α | B4: 5 | C4: Πλαίσιο διαχείρισης κινδύνων | D4: Βασικές και σημαντικές | E4: Πλαίσιο διαχείρισης κινδύνων κυβερνοασφάλειας, ευθυγραμμισμένο με τη διαχείριση επιχειρηματικών κινδύνων, με πρόβλεψη για τρίτα μέρη. | F4: Οργανωτικό ή εκτός Microsoft 365 | G4: Δεν καλύπτεται από ρύθμιση. Το Microsoft 365 δίνει μόνο δεδομένα εισόδου (Secure Score, Exposure Management). | H4: Εγκεκριμένη μεθοδολογία διαχείρισης κινδύνων. | I4: Microsoft Defender for Endpoint Plan 2 (Microsoft 365 E5 ή αντίστοιχο) | K4: https://thecybersec.gr/mitroo-politikon/
A5: 5.1.β | B5: 5 | C5: Πλαίσιο διαχείρισης κινδύνων | D5: Βασικές και σημαντικές | E5: Περιοδική εκτίμηση κινδύνων (risk assessment) με μεθοδολογία βασισμένη σε διεθνή πρότυπα. | F5: Μικτό | G5: Microsoft Secure Score και Microsoft Defender Vulnerability Management ως τεχνική είσοδος στην εκτίμηση κινδύνων. | H5: Μητρώο κινδύνων. Secure Score: History και τάση βαθμολογίας. | I5: Microsoft Defender for Endpoint Plan 2 ή Microsoft Defender Vulnerability Management standalone | K5: https://thecybersec.gr/posts/secure-score-grc-part-3-operations/ https://thecybersec.gr/posts/secure-score-defender-praktikos-odigos/ https://thecybersec.gr/mitroo-politikon/
A6: 5.1.γ | B6: 5 | C6: Πλαίσιο διαχείρισης κινδύνων | D6: Βασικές και σημαντικές | E6: Πλάνο αντιμετώπισης κινδύνων (risk treatment plan) με κριτήρια προτεραιοποίησης. | F6: Μικτό | G6: Κατάσταση ανά recommendation στο Secure Score (To address, Planned, Risk accepted, Resolved through third party, Resolved through alternate mitigation) ως το τεχνικό σκέλος του πλάνου. | H6: Secure Score: Recommended actions με status και σημειώσεις. Εγκεκριμένο risk treatment plan. | K6: https://thecybersec.gr/posts/secure-score-grc-part-3-operations/ https://thecybersec.gr/posts/secure-score-grc-part-1-anatomy/ https://thecybersec.gr/mitroo-politikon/
A7: 5.1.δ | B7: 5 | C7: Πλαίσιο διαχείρισης κινδύνων | D7: Βασικές και σημαντικές | E7: Αξιολόγηση και επικαιροποίηση εκτίμησης και πλάνου σε προγραμματισμένα διαστήματα και μετά από σοβαρά περιστατικά ή αλλαγές. | F7: Μικτό | G7: Secure Score History και Compliance Manager για την τεκμηρίωση της περιοδικής επανεξέτασης. | H7: Ημερολόγιο αναθεωρήσεων, εκδόσεις μητρώου κινδύνων. | K7: https://thecybersec.gr/posts/secure-score-grc-part-3-operations/
A8: 5.2 | B8: 5 | C8: Πλαίσιο διαχείρισης κινδύνων | D8: Μόνο βασικές | E8: Εμπεριστατωμένη εκτίμηση κινδύνων με cyber threat intelligence και πλήρη αξιολόγηση ευπαθειών. | F8: Μικτό | G8: Threat analytics στο Microsoft Defender XDR για threat intelligence. Microsoft Defender Vulnerability Management για την αξιολόγηση ευπαθειών. | H8: Defender portal: Threat analytics, Vulnerability management (Weaknesses, Recommendations). | I8: Microsoft Defender for Endpoint Plan 2 (περιλαμβάνεται στο Microsoft 365 E5). Εναλλακτικά Microsoft Defender Vulnerability Management standalone για την αξιολόγηση ευπαθειών. | K8: https://thecybersec.gr/posts/previews/vulnerability-remediation-agent-intune/ https://thecybersec.gr/posts/microsoft-defender-oikogeneia-praktikos-odigos/
A9: 6.α | B9: 6 | C9: Πολιτικές και διαδικασίες ασφάλειας πληροφοριών | D9: Βασικές και σημαντικές | E9: Γραπτή γενική πολιτική ασφάλειας πληροφοριών, εγκεκριμένη από το ανώτατο όργανο διοίκησης. | F9: Οργανωτικό ή εκτός Microsoft 365 | G9: Δεν καλύπτεται από ρύθμιση. SharePoint Online για ελεγχόμενη διανομή και ιστορικό εκδόσεων του εγγράφου. | H9: Εγκεκριμένη πολιτική με αριθμό έκδοσης και ημερομηνία. | K9: https://thecybersec.gr/mitroo-politikon/
A10: 6.β | B10: 6 | C10: Πολιτικές και διαδικασίες ασφάλειας πληροφοριών | D10: Βασικές και σημαντικές | E10: Έντεκα ελάχιστες θεματικές πολιτικές (πρόσβαση, αγαθά, ορθή χρήση, αφαιρούμενα μέσα, περιστατικά, εφοδιαστική αλυσίδα, δίκτυα, έλεγχοι, αντίγραφα ασφαλείας, κρυπτογράφηση, φυσική ασφάλεια). | F10: Οργανωτικό ή εκτός Microsoft 365 | G10: Οι πολιτικές είναι έγγραφα. Η τεχνική εφαρμογή κάθε πολιτικής αντιστοιχίζεται στα άρθρα 11, 12, 13, 18, 19, 22, 23, 24 και 25 αυτού του πίνακα. | H10: Οι έντεκα εγκεκριμένες θεματικές πολιτικές. | K10: https://thecybersec.gr/mitroo-politikon/
A11: 6.γ | B11: 6 | C11: Πολιτικές και διαδικασίες ασφάλειας πληροφοριών | D11: Βασικές και σημαντικές | E11: Αξιολόγηση και επικαιροποίηση των πολιτικών σε προγραμματισμένα διαστήματα και μετά από σοβαρά περιστατικά ή αλλαγές. | F11: Οργανωτικό ή εκτός Microsoft 365 | G11: Δεν καλύπτεται από ρύθμιση. | H11: Ιστορικό αναθεωρήσεων πολιτικών. | K11: https://thecybersec.gr/mitroo-politikon/
A12: 7.α | B12: 7 | C12: Ρόλοι, αρμοδιότητες και εξουσίες | D12: Βασικές και σημαντικές | E12: Ορισμός αρμοδιοτήτων και εξουσιών κυβερνοασφάλειας σε ρόλους, και ορισμός Υ.Α.Σ.Π.Ε. | F12: Μικτό | G12: Microsoft Entra ID roles (π.χ. Security Administrator, Security Reader, Compliance Administrator) ως τεχνική αποτύπωση των ρόλων. | H12: Απόφαση ορισμού Υ.Α.Σ.Π.Ε. Entra admin center: Roles and administrators (assignments). | K12: https://thecybersec.gr/posts/secure-score-defender-praktikos-odigos/ https://thecybersec.gr/mitroo-politikon/
A13: 7.β | B13: 7 | C13: Ρόλοι, αρμοδιότητες και εξουσίες | D13: Βασικές και σημαντικές | E13: Ο Υ.Α.Σ.Π.Ε. αναφέρεται απευθείας στο ανώτατο όργανο διοίκησης. | F13: Οργανωτικό ή εκτός Microsoft 365 | G13: Δεν καλύπτεται από ρύθμιση. | H13: Οργανόγραμμα, γραμμή αναφοράς, αναφορές Υ.Α.Σ.Π.Ε. προς το ΔΣ.
A14: 7.γ | B14: 7 | C14: Ρόλοι, αρμοδιότητες και εξουσίες | D14: Βασικές και σημαντικές | E14: Περιοδική αξιολόγηση και επικαιροποίηση ρόλων, αρμοδιοτήτων και εξουσιών. | F14: Μικτό | G14: Access reviews για τις αναθέσεις ρόλων (Microsoft Entra ID Governance). | H14: Αποτελέσματα access reviews, πρακτικά αναθεώρησης ρόλων. | I14: Microsoft Entra ID Governance ή Microsoft Entra ID P2
A15: 8.α | B15: 8 | C15: Ανεξάρτητος έλεγχος ασφάλειας πληροφοριών | D15: Μόνο βασικές | E15: Περιοδικοί ανεξάρτητοι έλεγχοι (independent audits) του προγράμματος ασφάλειας πληροφοριών. | F15: Μικτό | G15: Πρόσβαση μόνο για ανάγνωση στον ελεγκτή (Global Reader, Security Reader) και dashboard τεκμηρίων από Secure Score μέσω Microsoft Graph και Power BI. | H15: Εκθέσεις ελέγχου. Power BI dashboard με ιστορικό Secure Score. | K15: https://thecybersec.gr/posts/secure-score-grc-part-0-intro/ https://thecybersec.gr/posts/secure-score-grc-part-3-operations/ https://thecybersec.gr/mitroo-politikon/
A16: 8.β | B16: 8 | C16: Ανεξάρτητος έλεγχος ασφάλειας πληροφοριών | D16: Μόνο βασικές | E16: Διασφάλιση αμεροληψίας των ελεγκτών. | F16: Οργανωτικό ή εκτός Microsoft 365 | G16: Δεν καλύπτεται από ρύθμιση. | H16: Δήλωση ανεξαρτησίας ελεγκτή.
A17: 8.γ | B17: 8 | C17: Ανεξάρτητος έλεγχος ασφάλειας πληροφοριών | D17: Μόνο βασικές | E17: Διορθωτικές ενέργειες από το ανώτατο όργανο όταν ο έλεγχος δείξει ανεπάρκεια. | F17: Μικτό | G17: Παρακολούθηση των τεχνικών διορθωτικών ενεργειών ως recommendations στο Secure Score και improvement actions στο Compliance Manager. | H17: Πλάνο διορθωτικών ενεργειών με κατάσταση και ημερομηνίες. | K17: https://thecybersec.gr/posts/secure-score-grc-part-3-operations/
A18: 8.δ | B18: 8 | C18: Ανεξάρτητος έλεγχος ασφάλειας πληροφοριών | D18: Μόνο βασικές | E18: Έλεγχοι σε προγραμματισμένα διαστήματα και μετά από σοβαρά περιστατικά ή αλλαγές. | F18: Οργανωτικό ή εκτός Microsoft 365 | G18: Δεν καλύπτεται από ρύθμιση. | H18: Πρόγραμμα ελέγχων.
A19: 9.α | B19: 9 | C19: Διαδικασίες παρακολούθησης της συμμόρφωσης | D19: Βασικές και σημαντικές | E19: Διαδικασίες παρακολούθησης της συμμόρφωσης με τις κανονιστικές υποχρεώσεις και περιοδική αναφορά στο ανώτατο όργανο. | F19: Μικτό | G19: Microsoft Purview Compliance Manager με τα assessments «NIS2 Directive (EU) 2022/2555» και «ISO/IEC 27001:2022», συνδεδεμένα με το Secure Score. | H19: Compliance Manager: assessment score και εξαγωγή αναφοράς. Αναφορά προς το ΔΣ. | I19: Premium regulations του Compliance Manager για NIS 2 και ISO/IEC 27001:2022 (αγοράζονται ξεχωριστά, ή ως δύο από τα τρία δωρεάν premium regulations με Microsoft 365 E5) | K19: https://thecybersec.gr/posts/secure-score-grc-part-0-intro/ https://thecybersec.gr/posts/secure-score-grc-part-3-operations/ https://thecybersec.gr/mitroo-politikon/
A20: 9.β | B20: 9 | C20: Διαδικασίες παρακολούθησης της συμμόρφωσης | D20: Βασικές και σημαντικές | E20: Διορθωτικές ενέργειες σε περίπτωση μη συμμόρφωσης. | F20: Μικτό | G20: Ανάθεση improvement actions σε υπευθύνους στο Compliance Manager. | H20: Κατάσταση improvement actions με υπεύθυνο και ημερομηνία. | K20: https://thecybersec.gr/posts/secure-score-grc-part-3-operations/
A21: 9.γ | B21: 9 | C21: Διαδικασίες παρακολούθησης της συμμόρφωσης | D21: Βασικές και σημαντικές | E21: Παρακολούθηση σε προγραμματισμένα διαστήματα και όταν αλλάζει το κανονιστικό πλαίσιο ή οι λειτουργίες. | F21: Μικτό | G21: Το Compliance Manager ειδοποιεί όταν η Microsoft αναθεωρεί ένα template, ώστε να ενημερωθεί το assessment. | H21: Ημερολόγιο αναθεωρήσεων συμμόρφωσης. | K21: https://thecybersec.gr/posts/secure-score-grc-part-3-operations/
A22: 10.1.α | B22: 10 | C22: Ασφάλεια ανθρώπινου δυναμικού | D22: Βασικές και σημαντικές | E22: Έλεγχοι καταλληλότητας του υποψήφιου προσωπικού. | F22: Οργανωτικό ή εκτός Microsoft 365 | G22: Δεν καλύπτεται από ρύθμιση. | H22: Διαδικασία HR, αρχεία προσλήψεων. | K22: https://thecybersec.gr/mitroo-politikon/
A23: 10.1.β | B23: 10 | C23: Ασφάλεια ανθρώπινου δυναμικού | D23: Βασικές και σημαντικές | E23: Ευθύνες και καθήκοντα που παραμένουν μετά τη λήξη ή αλλαγή της απασχόλησης. | F23: Οργανωτικό ή εκτός Microsoft 365 | G23: Δεν καλύπτεται από ρύθμιση. | H23: Όροι σύμβασης, ρήτρες εμπιστευτικότητας.
A24: 10.1.γ | B24: 10 | C24: Ασφάλεια ανθρώπινου δυναμικού | D24: Βασικές και σημαντικές | E24: Διαδικασίες πειθαρχικού ελέγχου για παραβίαση των πολιτικών ασφάλειας. | F24: Οργανωτικό ή εκτός Microsoft 365 | G24: Δεν καλύπτεται από ρύθμιση. | H24: Πειθαρχική διαδικασία.
A25: 10.2 | B25: 10 | C25: Ασφάλεια ανθρώπινου δυναμικού | D25: Μόνο βασικές | E25: Επαλήθευση ιστορικού (background checks) για προσωπικό με ρόλους κυβερνοασφάλειας. | F25: Οργανωτικό ή εκτός Microsoft 365 | G25: Δεν καλύπτεται από ρύθμιση. | H25: Αρχεία ελέγχου ιστορικού.
A26: 11.α | B26: 11 | C26: Διαχείριση υλικού και λογισμικού | D26: Βασικές και σημαντικές | E26: Ακριβής και ενημερωμένος κατάλογος αγαθών (υλικό, λογισμικό, συστήματα, δεδομένα, υπηρεσίες, cloud και OT), με ιδιοκτήτη ανά αγαθό. | F26: Μικτό | G26: Device inventory στο Microsoft Defender for Endpoint και στο Microsoft Intune. Software inventory στο Defender Vulnerability Management. Cloud Discovery στο Microsoft Defender for Cloud Apps για τις cloud υπηρεσίες. Τα αγαθά OT δεν καλύπτονται από το Microsoft 365. Καλύπτονται από το Microsoft Defender for IoT, που είναι ξεχωριστό προϊόν. | H26: Defender portal: Assets, Devices. Intune: Devices. Εξαγωγές καταλόγου. | I26: Microsoft Defender for Endpoint Plan 2 ή Microsoft Defender Vulnerability Management standalone (software inventory, πλήρες device inventory). Microsoft Defender for IoT (για τα αγαθά OT). | J26: Ο ορισμός ιδιοκτήτη (owner) ανά αγαθό δεν καλύπτεται από προϊόντα Microsoft. Τηρείται σε ξεχωριστό μητρώο αγαθών. | K26: https://thecybersec.gr/posts/microsoft-defender-xdr-full-tutorial-ciso/ https://thecybersec.gr/posts/microsoft-defender-oikogeneia-praktikos-odigos/ https://thecybersec.gr/posts/defender-demystified-series/defender-demystified-part-2-four-workloads/ https://thecybersec.gr/posts/microsoft-defender-up-close-series/microsoft-defender-for-endpoint-deep-dive/ https://thecybersec.gr/posts/microsoft-defender-up-close-series/microsoft-defender-for-cloud-apps-deep-dive/ https://thecybersec.gr/mitroo-politikon/
A27: 11.β | B27: 11 | C27: Διαχείριση υλικού και λογισμικού | D27: Βασικές και σημαντικές | E27: Ταξινόμηση δεδομένων και αγαθών σε επίπεδα, με βάση εμπιστευτικότητα, ακεραιότητα και διαθεσιμότητα. | F27: Τεχνικό | G27: Sensitivity labels στο Microsoft Purview Information Protection και auto-labeling. Critical asset management στο Microsoft Security Exposure Management για την κρισιμότητα συσκευών και ταυτοτήτων. | H27: Purview portal: Information protection, Labels και Label policies. Content explorer. | I27: Microsoft 365 E5 ή Microsoft Purview Suite (auto-labeling και Content explorer). Microsoft Defender for Endpoint Plan 2 (Microsoft 365 E5 ή αντίστοιχο) | K27: https://thecybersec.gr/posts/purview-autolabeling-500k-scale-increase/ https://thecybersec.gr/mitroo-politikon/
A28: 11.γ | B28: 11 | C28: Διαχείριση υλικού και λογισμικού | D28: Βασικές και σημαντικές | E28: Γραπτή πολιτική και οδηγίες ορθής χρήσης αγαθών και δεδομένων σε όλο τον κύκλο ζωής. | F28: Μικτό | G28: Microsoft Purview Data Loss Prevention και retention policies (Data Lifecycle Management) για την τεχνική επιβολή. Retire και Wipe στο Intune για την ασφαλή απομάκρυνση. | H28: Εγκεκριμένη πολιτική. Purview: DLP policies και retention policies. | K28: https://thecybersec.gr/posts/purview-autolabeling-500k-scale-increase/ https://thecybersec.gr/posts/previews/defender-endpoint-ai-agent-runtime-protection-intune/ https://thecybersec.gr/posts/microsoft-defender-up-close-series/microsoft-defender-for-cloud-apps-deep-dive/ https://thecybersec.gr/mitroo-politikon/
A29: 11.δ | B29: 11 | C29: Διαχείριση υλικού και λογισμικού | D29: Βασικές και σημαντικές | E29: Γραπτή πολιτική για την ασφαλή διαχείριση αφαιρούμενων μέσων αποθήκευσης. | F29: Μικτό | G29: Device control (removable storage access control) στο Defender for Endpoint μέσω Intune. BitLocker To Go για κρυπτογράφηση αφαιρούμενων μέσων. | H29: Εγκεκριμένη πολιτική. Intune: Endpoint security, Attack surface reduction, Device control. | K29: https://thecybersec.gr/mitroo-politikon/
A30: 12.1.α | B30: 12 | C30: Διαχείριση κινδύνων από τις σχέσεις με προμηθευτές και παρόχους υπηρεσιών Τ.Π.Ε. | D30: Βασικές και σημαντικές | E30: Πολιτική και διαδικασίες για τις σχέσεις με προμηθευτές και παρόχους υπηρεσιών Τ.Π.Ε. | F30: Οργανωτικό ή εκτός Microsoft 365 | G30: Δεν καλύπτεται από ρύθμιση. | H30: Εγκεκριμένη πολιτική ασφάλειας εφοδιαστικής αλυσίδας. | K30: https://thecybersec.gr/mitroo-politikon/
A31: 12.1.β | B31: 12 | C31: Διαχείριση κινδύνων από τις σχέσεις με προμηθευτές και παρόχους υπηρεσιών Τ.Π.Ε. | D31: Βασικές και σημαντικές | E31: Ενημερωμένος κατάλογος άμεσων προμηθευτών και παρόχων, με σημεία επαφής, προϊόντα/υπηρεσίες και ταξινόμηση κρισιμότητας. | F31: Μικτό | G31: Cloud Discovery και cloud app catalog στο Defender for Cloud Apps για να εντοπιστούν οι cloud πάροχοι που χρησιμοποιούνται πραγματικά. Enterprise applications στο Entra ID για τις εφαρμογές τρίτων με πρόσβαση στο tenant. | H31: Μητρώο προμηθευτών. Defender portal: Cloud apps, Cloud discovery, Discovered apps. | K31: https://thecybersec.gr/posts/microsoft-defender-xdr-full-tutorial-ciso/ https://thecybersec.gr/mitroo-politikon/
A32: 12.1.γ | B32: 12 | C32: Διαχείριση κινδύνων από τις σχέσεις με προμηθευτές και παρόχους υπηρεσιών Τ.Π.Ε. | D32: Βασικές και σημαντικές | E32: Διαδικασίες διαχείρισης κινδύνων προμηθευτών σε όλο τον κύκλο ζωής: κριτήρια αξιολόγησης και απαιτήσεις κυβερνοασφάλειας για παρόχους και προϊόντα. | F32: Μικτό | G32: Risk score ανά cloud εφαρμογή στο Defender for Cloud Apps (πιστοποιήσεις, συμμόρφωση) ως κριτήριο αξιολόγησης. Ρύθμιση Allowed Agent Types «Only certified external publishers». Service Trust Portal για τις εκθέσεις ελέγχου της ίδιας της Microsoft. | H32: Αρχεία αξιολόγησης προμηθευτών. Cloud app catalog: risk score. Microsoft 365 admin center: Allowed agent types. | K32: https://thecybersec.gr/posts/allowed-agent-types-only-certified-external-publishers/ https://thecybersec.gr/posts/microsoft-defender-xdr-full-tutorial-ciso/ https://thecybersec.gr/posts/gsa-mcp-firewall/ https://thecybersec.gr/posts/microsoft-defender-up-close-series/microsoft-defender-for-cloud-apps-deep-dive/ https://thecybersec.gr/mitroo-politikon/
A33: 12.1.δ | B33: 12 | C33: Διαχείριση κινδύνων από τις σχέσεις με προμηθευτές και παρόχους υπηρεσιών Τ.Π.Ε. | D33: Βασικές και σημαντικές | E33: Ελάχιστο περιεχόμενο συμβάσεων: απαιτήσεις ασφάλειας, συστήματα και δεδομένα στα οποία αποκτά πρόσβαση ο προμηθευτής, δικαίωμα ελέγχου, ασφαλής λήξη. | F33: Μικτό | G33: Οι συμβάσεις είναι οργανωτικό μέτρο. Για την πρόσβαση και την ασφαλή λήξη: cross-tenant access settings, guest accounts με access reviews και αφαίρεση δικαιωμάτων στο Entra ID. | H33: Υπογεγραμμένες συμβάσεις. Entra admin center: External Identities, Cross-tenant access settings. | I33: Microsoft Entra ID Governance ή Microsoft Entra ID P2 (access reviews) | K33: https://thecybersec.gr/posts/generally-available/cross-tenant-message-recall-exchange-online/ https://thecybersec.gr/posts/entra-tenant-governance-ga/
A34: 12.1.ε | B34: 12 | C34: Διαχείριση κινδύνων από τις σχέσεις με προμηθευτές και παρόχους υπηρεσιών Τ.Π.Ε. | D34: Βασικές και σημαντικές | E34: Περιοδική αξιολόγηση και επικαιροποίηση πολιτικών και διαδικασιών προμηθευτών. | F34: Οργανωτικό ή εκτός Microsoft 365 | G34: Δεν καλύπτεται από ρύθμιση. | H34: Ιστορικό αναθεωρήσεων.
A35: 12.2.α | B35: 12 | C35: Διαχείριση κινδύνων από τις σχέσεις με προμηθευτές και παρόχους υπηρεσιών Τ.Π.Ε. | D35: Μόνο βασικές | E35: Ενισχυμένες απαιτήσεις κυβερνοασφάλειας για τους κρίσιμους προμηθευτές και παρόχους. | F35: Μικτό | G35: Conditional Access για external users (MFA, compliant device) και cross-tenant access settings ανά οργανισμό-προμηθευτή. | H35: Συμβατικές απαιτήσεις. Conditional Access policies με target «Guest or external users». | K35: https://thecybersec.gr/posts/generally-available/cross-tenant-message-recall-exchange-online/ https://thecybersec.gr/posts/entra-tenant-governance-ga/ https://thecybersec.gr/posts/global-secure-access/global-secure-access-meros-5-conditional-access/
A36: 12.2.β | B36: 12 | C36: Διαχείριση κινδύνων από τις σχέσεις με προμηθευτές και παρόχους υπηρεσιών Τ.Π.Ε. | D36: Μόνο βασικές | E36: Επέκταση της διαχείρισης κινδύνων σε όλη την εφοδιαστική αλυσίδα, και σε υπεργολάβους. | F36: Οργανωτικό ή εκτός Microsoft 365 | G36: Δεν καλύπτεται από ρύθμιση. | H36: Συμβατικές ρήτρες για υπεργολάβους.
A37: 13.α | B37: 13 | C37: Διαχείριση λογαριασμών και έλεγχος πρόσβασης | D37: Βασικές και σημαντικές | E37: Πολιτική και διαδικασίες λογικού ελέγχου πρόσβασης, για προσωπικό και για τρίτους. | F37: Μικτό | G37: Conditional Access στο Microsoft Entra ID ως η τεχνική επιβολή της πολιτικής. | H37: Εγκεκριμένη πολιτική ελέγχου πρόσβασης. Entra admin center: Conditional Access, Policies. | K37: https://thecybersec.gr/posts/global-secure-access/global-secure-access-meros-5-conditional-access/ https://thecybersec.gr/mitroo-politikon/
A38: 13.β | B38: 13 | C38: Διαχείριση λογαριασμών και έλεγχος πρόσβασης | D38: Βασικές και σημαντικές | E38: Μοναδική ταυτότητα για κάθε χρήστη και σύστημα, ώστε να υπάρχει λογοδοσία. | F38: Τεχνικό | G38: Ατομικοί λογαριασμοί στο Microsoft Entra ID, χωρίς κοινόχρηστους λογαριασμούς. Service principals και managed identities για τα συστήματα. Συγχρονισμός από AD με Entra Connect ή Cloud Sync. | H38: Entra admin center: Users, Enterprise applications. Sign-in logs ανά ταυτότητα. | K38: https://thecybersec.gr/posts/microsoft-entra-architecture-guide-defender/ https://thecybersec.gr/posts/azure-kai-entra-to-themelio/ https://thecybersec.gr/posts/entra-connect-mandatory-upgrade-2026/
A39: 13.γ | B39: 13 | C39: Διαχείριση λογαριασμών και έλεγχος πρόσβασης | D39: Βασικές και σημαντικές | E39: Χορήγηση και ανάκληση δικαιωμάτων με least privilege, need to know και separation of duties. | F39: Τεχνικό | G39: Microsoft Entra ID roles και ανάθεση πρόσβασης μέσω groups. Access reviews και entitlement management (Microsoft Entra ID Governance). | H39: Role assignments, group memberships, αποτελέσματα access reviews. | I39: Microsoft Entra ID Governance ή Microsoft Entra ID P2 (access reviews και entitlement management) | K39: https://thecybersec.gr/posts/previews/ad-group-enforcement-cloud-sync/ https://thecybersec.gr/posts/entra-tenant-governance-ga/ https://thecybersec.gr/posts/microsoft-defender-up-close-series/microsoft-defender-for-cloud-apps-deep-dive/
A40: 13.δ | B40: 13 | C40: Διαχείριση λογαριασμών και έλεγχος πρόσβασης | D40: Βασικές και σημαντικές | E40: Περιορισμός των προνομιούχων λογαριασμών και των δικαιωμάτων διαχείρισης στο απολύτως απαραίτητο. | F40: Τεχνικό | G40: Privileged Identity Management (just-in-time ενεργοποίηση ρόλων με έγκριση). Περιορισμός του αριθμού των Global Administrators. Phishing-resistant MFA για τους administrators. | H40: PIM: eligible και active assignments, audit history. Secure Score: recommendations για admin roles. | I40: Microsoft Entra ID P2 (Privileged Identity Management) | K40: https://thecybersec.gr/posts/secure-score-grc-part-0-intro/ https://thecybersec.gr/posts/secure-score-grc-part-1-anatomy/ https://thecybersec.gr/posts/microsoft-defender-up-close-series/microsoft-defender-for-identity-deep-dive/
...

Sheet Σύνοψη
A1: Άρθρο | B1: Τίτλος άρθρου ΚΥΑ | C1: Απαιτήσεις | D1: Δεν ξεκίνησε | E1: Σε εξέλιξη | F1: Υλοποιήθηκε | G1: Δεν εφαρμόζεται | H1: Χωρίς κατάσταση | I1: Ολοκλήρωση
A2: 4 | B2: Υποχρεώσεις και ευθύνη των ανωτάτων οργάνων διοίκησης | C2: =COUNTIF(Checklist!$B$2:$B$112,A2) | D2: =COUNTIFS(Checklist!$B$2:$B$112,$A2,Checklist!$L$2:$L$112,"Δεν ξεκίνησε") | E2: =COUNTIFS(Checklist!$B$2:$B$112,$A2,Checklist!$L$2:$L$112,"Σε εξέλιξη") | F2: =COUNTIFS(Checklist!$B$2:$B$112,$A2,Checklist!$L$2:$L$112,"Υλοποιήθηκε") | G2: =COUNTIFS(Checklist!$B$2:$B$112,$A2,Checklist!$L$2:$L$112,"Δεν εφαρμόζεται") | H2: =C2-SUM(D2:G2) | I2: =IF(C2-G2=0,0,F2/(C2-G2))
A3: 5 | B3: Πλαίσιο διαχείρισης κινδύνων | C3: =COUNTIF(Checklist!$B$2:$B$112,A3) | D3: =COUNTIFS(Checklist!$B$2:$B$112,$A3,Checklist!$L$2:$L$112,"Δεν ξεκίνησε") | E3: =COUNTIFS(Checklist!$B$2:$B$112,$A3,Checklist!$L$2:$L$112,"Σε εξέλιξη") | F3: =COUNTIFS(Checklist!$B$2:$B$112,$A3,Checklist!$L$2:$L$112,"Υλοποιήθηκε") | G3: =COUNTIFS(Checklist!$B$2:$B$112,$A3,Checklist!$L$2:$L$112,"Δεν εφαρμόζεται") | H3: =C3-SUM(D3:G3) | I3: =IF(C3-G3=0,0,F3/(C3-G3))
A4: 6 | B4: Πολιτικές και διαδικασίες ασφάλειας πληροφοριών | C4: =COUNTIF(Checklist!$B$2:$B$112,A4) | D4: =COUNTIFS(Checklist!$B$2:$B$112,$A4,Checklist!$L$2:$L$112,"Δεν ξεκίνησε") | E4: =COUNTIFS(Checklist!$B$2:$B$112,$A4,Checklist!$L$2:$L$112,"Σε εξέλιξη") | F4: =COUNTIFS(Checklist!$B$2:$B$112,$A4,Checklist!$L$2:$L$112,"Υλοποιήθηκε") | G4: =COUNTIFS(Checklist!$B$2:$B$112,$A4,Checklist!$L$2:$L$112,"Δεν εφαρμόζεται") | H4: =C4-SUM(D4:G4) | I4: =IF(C4-G4=0,0,F4/(C4-G4))
A5: 7 | B5: Ρόλοι, αρμοδιότητες και εξουσίες | C5: =COUNTIF(Checklist!$B$2:$B$112,A5) | D5: =COUNTIFS(Checklist!$B$2:$B$112,$A5,Checklist!$L$2:$L$112,"Δεν ξεκίνησε") | E5: =COUNTIFS(Checklist!$B$2:$B$112,$A5,Checklist!$L$2:$L$112,"Σε εξέλιξη") | F5: =COUNTIFS(Checklist!$B$2:$B$112,$A5,Checklist!$L$2:$L$112,"Υλοποιήθηκε") | G5: =COUNTIFS(Checklist!$B$2:$B$112,$A5,Checklist!$L$2:$L$112,"Δεν εφαρμόζεται") | H5: =C5-SUM(D5:G5) | I5: =IF(C5-G5=0,0,F5/(C5-G5))
A6: 8 | B6: Ανεξάρτητος έλεγχος ασφάλειας πληροφοριών | C6: =COUNTIF(Checklist!$B$2:$B$112,A6) | D6: =COUNTIFS(Checklist!$B$2:$B$112,$A6,Checklist!$L$2:$L$112,"Δεν ξεκίνησε") | E6: =COUNTIFS(Checklist!$B$2:$B$112,$A6,Checklist!$L$2:$L$112,"Σε εξέλιξη") | F6: =COUNTIFS(Checklist!$B$2:$B$112,$A6,Checklist!$L$2:$L$112,"Υλοποιήθηκε") | G6: =COUNTIFS(Checklist!$B$2:$B$112,$A6,Checklist!$L$2:$L$112,"Δεν εφαρμόζεται") | H6: =C6-SUM(D6:G6) | I6: =IF(C6-G6=0,0,F6/(C6-G6))
A7: 9 | B7: Διαδικασίες παρακολούθησης της συμμόρφωσης | C7: =COUNTIF(Checklist!$B$2:$B$112,A7) | D7: =COUNTIFS(Checklist!$B$2:$B$112,$A7,Checklist!$L$2:$L$112,"Δεν ξεκίνησε") | E7: =COUNTIFS(Checklist!$B$2:$B$112,$A7,Checklist!$L$2:$L$112,"Σε εξέλιξη") | F7: =COUNTIFS(Checklist!$B$2:$B$112,$A7,Checklist!$L$2:$L$112,"Υλοποιήθηκε") | G7: =COUNTIFS(Checklist!$B$2:$B$112,$A7,Checklist!$L$2:$L$112,"Δεν εφαρμόζεται") | H7: =C7-SUM(D7:G7) | I7: =IF(C7-G7=0,0,F7/(C7-G7))
A8: 10 | B8: Ασφάλεια ανθρώπινου δυναμικού | C8: =COUNTIF(Checklist!$B$2:$B$112,A8) | D8: =COUNTIFS(Checklist!$B$2:$B$112,$A8,Checklist!$L$2:$L$112,"Δεν ξεκίνησε") | E8: =COUNTIFS(Checklist!$B$2:$B$112,$A8,Checklist!$L$2:$L$112,"Σε εξέλιξη") | F8: =COUNTIFS(Checklist!$B$2:$B$112,$A8,Checklist!$L$2:$L$112,"Υλοποιήθηκε") | G8: =COUNTIFS(Checklist!$B$2:$B$112,$A8,Checklist!$L$2:$L$112,"Δεν εφαρμόζεται") | H8: =C8-SUM(D8:G8) | I8: =IF(C8-G8=0,0,F8/(C8-G8))
A9: 11 | B9: Διαχείριση υλικού και λογισμικού | C9: =COUNTIF(Checklist!$B$2:$B$112,A9) | D9: =COUNTIFS(Checklist!$B$2:$B$112,$A9,Checklist!$L$2:$L$112,"Δεν ξεκίνησε") | E9: =COUNTIFS(Checklist!$B$2:$B$112,$A9,Checklist!$L$2:$L$112,"Σε εξέλιξη") | F9: =COUNTIFS(Checklist!$B$2:$B$112,$A9,Checklist!$L$2:$L$112,"Υλοποιήθηκε") | G9: =COUNTIFS(Checklist!$B$2:$B$112,$A9,Checklist!$L$2:$L$112,"Δεν εφαρμόζεται") | H9: =C9-SUM(D9:G9) | I9: =IF(C9-G9=0,0,F9/(C9-G9))
A10: 12 | B10: Διαχείριση κινδύνων από τις σχέσεις με προμηθευτές και παρόχους υπηρεσιών Τ.Π.Ε. | C10: =COUNTIF(Checklist!$B$2:$B$112,A10) | D10: =COUNTIFS(Checklist!$B$2:$B$112,$A10,Checklist!$L$2:$L$112,"Δεν ξεκίνησε") | E10: =COUNTIFS(Checklist!$B$2:$B$112,$A10,Checklist!$L$2:$L$112,"Σε εξέλιξη") | F10: =COUNTIFS(Checklist!$B$2:$B$112,$A10,Checklist!$L$2:$L$112,"Υλοποιήθηκε") | G10: =COUNTIFS(Checklist!$B$2:$B$112,$A10,Checklist!$L$2:$L$112,"Δεν εφαρμόζεται") | H10: =C10-SUM(D10:G10) | I10: =IF(C10-G10=0,0,F10/(C10-G10))
A11: 13 | B11: Διαχείριση λογαριασμών και έλεγχος πρόσβασης | C11: =COUNTIF(Checklist!$B$2:$B$112,A11) | D11: =COUNTIFS(Checklist!$B$2:$B$112,$A11,Checklist!$L$2:$L$112,"Δεν ξεκίνησε") | E11: =COUNTIFS(Checklist!$B$2:$B$112,$A11,Checklist!$L$2:$L$112,"Σε εξέλιξη") | F11: =COUNTIFS(Checklist!$B$2:$B$112,$A11,Checklist!$L$2:$L$112,"Υλοποιήθηκε") | G11: =COUNTIFS(Checklist!$B$2:$B$112,$A11,Checklist!$L$2:$L$112,"Δεν εφαρμόζεται") | H11: =C11-SUM(D11:G11) | I11: =IF(C11-G11=0,0,F11/(C11-G11))
A12: 14 | B12: Ασφαλής παραμετροποίηση υλικού, λογισμικού, υπηρεσιών και δικτύων | C12: =COUNTIF(Checklist!$B$2:$B$112,A12) | D12: =COUNTIFS(Checklist!$B$2:$B$112,$A12,Checklist!$L$2:$L$112,"Δεν ξεκίνησε") | E12: =COUNTIFS(Checklist!$B$2:$B$112,$A12,Checklist!$L$2:$L$112,"Σε εξέλιξη") | F12: =COUNTIFS(Checklist!$B$2:$B$112,$A12,Checklist!$L$2:$L$112,"Υλοποιήθηκε") | G12: =COUNTIFS(Checklist!$B$2:$B$112,$A12,Checklist!$L$2:$L$112,"Δεν εφαρμόζεται") | H12: =C12-SUM(D12:G12) | I12: =IF(C12-G12=0,0,F12/(C12-G12))
A13: 15 | B13: Αρχές ασφαλούς ανάπτυξης εφαρμογών | C13: =COUNTIF(Checklist!$B$2:$B$112,A13) | D13: =COUNTIFS(Checklist!$B$2:$B$112,$A13,Checklist!$L$2:$L$112,"Δεν ξεκίνησε") | E13: =COUNTIFS(Checklist!$B$2:$B$112,$A13,Checklist!$L$2:$L$112,"Σε εξέλιξη") | F13: =COUNTIFS(Checklist!$B$2:$B$112,$A13,Checklist!$L$2:$L$112,"Υλοποιήθηκε") | G13: =COUNTIFS(Checklist!$B$2:$B$112,$A13,Checklist!$L$2:$L$112,"Δεν εφαρμόζεται") | H13: =C13-SUM(D13:G13) | I13: =IF(C13-G13=0,0,F13/(C13-G13))
... A23: 25 | B23: Επιχειρησιακή συνέχεια και διαχείριση κρίσεων | C23: =COUNTIF(Checklist!$B$2:$B$112,A23) | D23: =COUNTIFS(Checklist!$B$2:$B$112,$A23,Checklist!$L$2:$L$112,"Δεν ξεκίνησε") | E23: =COUNTIFS(Checklist!$B$2:$B$112,$A23,Checklist!$L$2:$L$112,"Σε εξέλιξη") | F23: =COUNTIFS(Checklist!$B$2:$B$112,$A23,Checklist!$L$2:$L$112,"Υλοποιήθηκε") | G23: =COUNTIFS(Checklist!$B$2:$B$112,$A23,Checklist!$L$2:$L$112,"Δεν εφαρμόζεται") | H23: =C23-SUM(D23:G23) | I23: =IF(C23-G23=0,0,F23/(C23-G23))
B24: Σύνολο | C24: =SUM(C2:C23) | D24: =SUM(D2:D23) | E24: =SUM(E2:E23) | F24: =SUM(F2:F23) | G24: =SUM(G2:G23) | H24: =SUM(H2:H23) | I24: =IF(C24-G24=0,0,F24/(C24-G24))
